Workbook

Sheet Data
A1: Fab | B1: Issue Key | C1: Title | D1: Create Date | E1: Creater | F1: Tool ID | G1: Comment
A2: =INDEX(Reference!A:A,RANDBETWEEN(2,6)) -> F12 | B2: =INDEX(Reference!B:B,RANDBETWEEN(2,4))&"-"&ROW(A2) -> AAA-2 | C2: Pellentesque aliquet diam et quam mollis, nec sagittis odio pellentesque. | D2: =RANDBETWEEN(DATEVALUE("2020/01/01"),DATEVALUE("2025/01/01")) -> 44664 | E2: =INDEX(Reference!D:D,RANDBETWEEN(2,4)) -> Bala | F2: =INDEX(Reference!C:C,RANDBETWEEN(2,7))&"#"&RANDBETWEEN(10,300) -> ASDFG#49 | G2: 歡示喜流笑室穴話
A3: =INDEX(Reference!A:A,RANDBETWEEN(2,6)) -> F16 | B3: =INDEX(Reference!B:B,RANDBETWEEN(2,4))&"-"&ROW(A3) -> AAA-3 | C3: Proin elementum risus vitae arcu hendrerit, vitae eleifend odio tristique. | D3: =RANDBETWEEN(DATEVALUE("2020/01/01"),DATEVALUE("2025/01/01")) -> 44919 | E3: =INDEX(Reference!D:D,RANDBETWEEN(2,4)) -> Gama | F3: =INDEX(Reference!C:C,RANDBETWEEN(2,7))&"#"&RANDBETWEEN(10,300) -> RTYU#255 | G3: 久立雨包、古每世春院方，晚跟工虎高「婆生行發收嗎早」衣二亭甲流的跟放王休的昌叫給房工許尾海。年瓜只因老別男正京羊呀詞食進。
A4: =INDEX(Reference!A:A,RANDBETWEEN(2,6)) -> F15 | B4: =INDEX(Reference!B:B,RANDBETWEEN(2,4))&"-"&ROW(A4) -> CCC-4 | C4: Nunc vitae magna scelerisque, sollicitudin ipsum a, convallis quam. | D4: =RANDBETWEEN(DATEVALUE("2020/01/01"),DATEVALUE("2025/01/01")) -> 45414 | E4: =INDEX(Reference!D:D,RANDBETWEEN(2,4)) -> Gama | F4: =INDEX(Reference!C:C,RANDBETWEEN(2,7))&"#"&RANDBETWEEN(10,300) -> CVBN#211 | G4: 肖種白尼弟已幼明，怕定跑信果菜乾青棵平行們吃吧彩開古完良「元斤蛋清」抓安有黑讀知服兌就入同太斤良還日皮古叫開「完現打呀」七別幼姐你遠澡因問何吉我面園親毛午。
A5: =INDEX(Reference!A:A,RANDBETWEEN(2,6)) -> F15 | B5: =INDEX(Reference!B:B,RANDBETWEEN(2,4))&"-"&ROW(A5) -> AAA-5 | C5: Nam sed orci a quam ultrices finibus. | D5: =RANDBETWEEN(DATEVALUE("2020/01/01"),DATEVALUE("2025/01/01")) -> 45400 | E5: =INDEX(Reference!D:D,RANDBETWEEN(2,4)) -> Gama | F5: =INDEX(Reference!C:C,RANDBETWEEN(2,7))&"#"&RANDBETWEEN(10,300) -> QWERT#84 | G5: 完父辛亭乞乞秋八念吉樹幾躲光也親哪「放幫」共胡牠呀外貫怪連奶中問大乾黑。辛門消信朵山鴨功息，念亭男間苦王了千肉抱王弓語去寸要澡枝鼻河，從室抓巾女生王幫澡錯。巴民祖色鴨這至色。
A6: =INDEX(Reference!A:A,RANDBETWEEN(2,6)) -> F12 | B6: =INDEX(Reference!B:B,RANDBETWEEN(2,4))&"-"&ROW(A6) -> AAA-6 | C6: Sed a velit elementum ante pellentesque auctor ac vitae dui. | D6: =RANDBETWEEN(DATEVALUE("2020/01/01"),DATEVALUE("2025/01/01")) -> 45162 | E6: =INDEX(Reference!D:D,RANDBETWEEN(2,4)) -> Bala | F6: =INDEX(Reference!C:C,RANDBETWEEN(2,7))&"#"&RANDBETWEEN(10,300) -> GHJK#260 | G6: 停朵但里旁故包和加明大再世呢動穿祖朱。法大抄月去會隻雄，陽花看田不草回能吧眼吹院草而法完「升姊拍跟丁知就」聲能色東「乾室汁」國浪支即壯牙書孝找送象斗秋金。跑常玉功登左和雲果原冬幫這你祖入多？杯直那。
A7: =INDEX(Reference!A:A,RANDBETWEEN(2,6)) -> F14 | B7: =INDEX(Reference!B:B,RANDBETWEEN(2,4))&"-"&ROW(A7) -> BBB-7 | C7: Etiam efficitur ante nec elit sagittis, non vulputate quam ullamcorper. | D7: =RANDBETWEEN(DATEVALUE("2020/01/01"),DATEVALUE("2025/01/01")) -> 45544 | E7: =INDEX(Reference!D:D,RANDBETWEEN(2,4)) -> Gama | F7: =INDEX(Reference!C:C,RANDBETWEEN(2,7))&"#"&RANDBETWEEN(10,300) -> RTYU#25 | G7: 且手光房化乞長、因起消乞杯父看對誰果跳童幼消旁頭別胡再，童科車功點嗎信工不皮行從草胡能話菜告，拉葉怕包。福元巾王怕東種？八田斗刀九躲尺男草乙、即玉種園吃日已寺念，米游吹細看笑新早收借。
A8: =INDEX(Reference!A:A,RANDBETWEEN(2,6)) -> F16 | B8: =INDEX(Reference!B:B,RANDBETWEEN(2,4))&"-"&ROW(A8) -> CCC-8 | C8: Suspendisse efficitur risus a dui finibus, ut faucibus metus suscipit. | D8: =RANDBETWEEN(DATEVALUE("2020/01/01"),DATEVALUE("2025/01/01")) -> 44685 | E8: =INDEX(Reference!D:D,RANDBETWEEN(2,4)) -> Gama | F8: =INDEX(Reference!C:C,RANDBETWEEN(2,7))&"#"&RANDBETWEEN(10,300) -> RTYU#224 | G8: 夏法的長花牠「右蝴羽見喝國里」笑玉找爬結從可、冒尾那胡竹雲。主元品珠法課、雨兩兌借胡娘，眼了兆帶即消。
A9: =INDEX(Reference!A:A,RANDBETWEEN(2,6)) -> F15 | B9: =INDEX(Reference!B:B,RANDBETWEEN(2,4))&"-"&ROW(A9) -> BBB-9 | C9: Curabitur sed felis sed lorem vehicula pulvinar ut eget urna. | D9: =RANDBETWEEN(DATEVALUE("2020/01/01"),DATEVALUE("2025/01/01")) -> 44422 | E9: =INDEX(Reference!D:D,RANDBETWEEN(2,4)) -> Suaya | F9: =INDEX(Reference!C:C,RANDBETWEEN(2,7))&"#"&RANDBETWEEN(10,300) -> CVBN#292 | G9: 消細心？巾風發生白八八急知歌澡過坡兆，泉菜河青比但問西習一空肉蛋布小追吉，忍氣海娘穿怕她午象道洋刀師加和唱。你喝貫親尾外浪後。
A10: =INDEX(Reference!A:A,RANDBETWEEN(2,6)) -> F15 | B10: =INDEX(Reference!B:B,RANDBETWEEN(2,4))&"-"&ROW(A10) -> CCC-10 | C10: Sed nec dui in nisl volutpat ultricies a a velit. | D10: =RANDBETWEEN(DATEVALUE("2020/01/01"),DATEVALUE("2025/01/01")) -> 44322 | E10: =INDEX(Reference!D:D,RANDBETWEEN(2,4)) -> Bala | F10: =INDEX(Reference!C:C,RANDBETWEEN(2,7))&"#"&RANDBETWEEN(10,300) -> CVBN#152 | G10: 頁午甲服示國友法話戊黃課金他幸向兄紅種海，讀高直「成反」枝歡園見想冰；爪課出信園色也蝸打浪勿告愛二去七叫福。穿年福屋或京王央更很：許貫北戊不發火肖就黃蛋草葉何，今玉往什娘流說因嗎着果快每躲。
A11: =INDEX(Reference!A:A,RANDBETWEEN(2,6)) -> F12 | B11: =INDEX(Reference!B:B,RANDBETWEEN(2,4))&"-"&ROW(A11) -> CCC-11 | C11: Vivamus vehicula ex at ex facilisis pellentesque. | D11: =RANDBETWEEN(DATEVALUE("2020/01/01"),DATEVALUE("2025/01/01")) -> 43832 | E11: =INDEX(Reference!D:D,RANDBETWEEN(2,4)) -> Gama | F11: =INDEX(Reference!C:C,RANDBETWEEN(2,7))&"#"&RANDBETWEEN(10,300) -> QWERT#254 | G11: 但雨花乞朱葉房也汗己個：成奶是火以村裏石您坐十封波昌合七京一屋帶，玩實因冬兄着頭地友象久很！位見澡那連冰眼地，畫完苗時，鳥身雄休過孝身田念停直問後。
A12: =INDEX(Reference!A:A,RANDBETWEEN(2,6)) -> F14 | B12: =INDEX(Reference!B:B,RANDBETWEEN(2,4))&"-"&ROW(A12) -> BBB-12 | C12: Nam at ligula sed velit molestie dignissim. | D12: =RANDBETWEEN(DATEVALUE("2020/01/01"),DATEVALUE("2025/01/01")) -> 44269 | E12: =INDEX(Reference!D:D,RANDBETWEEN(2,4)) -> Suaya | F12: =INDEX(Reference!C:C,RANDBETWEEN(2,7))&"#"&RANDBETWEEN(10,300) -> ZXCVB#69 | G12: 子物每香往戊教文以新邊抱，幼戶把家高條示加太春師支斗植九昌吉甲。訴具根已現三進物，世乞登珠屋幸隻斗拍蛋木和枝動對造，喜牠珠「彩但身歡祖對叫」。
A13: =INDEX(Reference!A:A,RANDBETWEEN(2,6)) -> F12 | B13: =INDEX(Reference!B:B,RANDBETWEEN(2,4))&"-"&ROW(A13) -> BBB-13 | C13: Sed venenatis metus quis nunc aliquet, sit amet varius est iaculis. | D13: =RANDBETWEEN(DATEVALUE("2020/01/01"),DATEVALUE("2025/01/01")) -> 43856 | E13: =INDEX(Reference!D:D,RANDBETWEEN(2,4)) -> Suaya | F13: =INDEX(Reference!C:C,RANDBETWEEN(2,7))&"#"&RANDBETWEEN(10,300) -> ZXCVB#36 | G13: 根玩忍背但彩少水發苗太汗。胡下斤春嗎第枝刀。地口讀什春孝；二乾邊羊杯植婆牠才乙頭嗎且亮穴兒記而意刃。抓冒化明，冰裏水久四。
... A44: =INDEX(Reference!A:A,RANDBETWEEN(2,6)) -> F12 | B44: =INDEX(Reference!B:B,RANDBETWEEN(2,4))&"-"&ROW(A44) -> AAA-44 | C44: Aenean nec purus at augue porttitor pulvinar. | D44: =RANDBETWEEN(DATEVALUE("2020/01/01"),DATEVALUE("2025/01/01")) -> 45084 | E44: =INDEX(Reference!D:D,RANDBETWEEN(2,4)) -> Suaya | F44: =INDEX(Reference!C:C,RANDBETWEEN(2,7))&"#"&RANDBETWEEN(10,300) -> ZXCVB#245 | G44: 冰戊林院字久魚勿，的後邊們忍午水唱穴爪胡原羽重米工笑，民寫追他它果祖杯澡課打借冬黃向斥平，校浪多裏事；真兩吹目化麻語老丁晚，山南汁平叫勿知良由亭兩蝶鼻十裏兆刀，節月英他：口荷昌。
A45: =INDEX(Reference!A:A,RANDBETWEEN(2,6)) -> F18 | B45: =INDEX(Reference!B:B,RANDBETWEEN(2,4))&"-"&ROW(A45) -> CCC-45 | C45: Ut ullamcorper lacus sit amet purus accumsan posuere. | D45: =RANDBETWEEN(DATEVALUE("2020/01/01"),DATEVALUE("2025/01/01")) -> 44918 | E45: =INDEX(Reference!D:D,RANDBETWEEN(2,4)) -> Gama | F45: =INDEX(Reference!C:C,RANDBETWEEN(2,7))&"#"&RANDBETWEEN(10,300) -> ASDFG#76
A46: =INDEX(Reference!A:A,RANDBETWEEN(2,6)) -> F12 | B46: =INDEX(Reference!B:B,RANDBETWEEN(2,4))&"-"&ROW(A46) -> BBB-46 | C46: Sed interdum libero ut velit sagittis consequat. | D46: =RANDBETWEEN(DATEVALUE("2020/01/01"),DATEVALUE("2025/01/01")) -> 45333 | E46: =INDEX(Reference!D:D,RANDBETWEEN(2,4)) -> Gama | F46: =INDEX(Reference!C:C,RANDBETWEEN(2,7))&"#"&RANDBETWEEN(10,300) -> CVBN#193 | G46: 重看入飛得聲布喜雞你告斥給尾麻急杯兆，了村可打、苗冰黃直造鴨從定固九家道前方老化快再幾。吧都午包象老工幾間吃兆？着夏父裝來百黃休尤就面浪以聽過哥。
A47: =INDEX(Reference!A:A,RANDBETWEEN(2,6)) -> F12 | B47: =INDEX(Reference!B:B,RANDBETWEEN(2,4))&"-"&ROW(A47) -> BBB-47 | C47: Cras quis risus quis neque imperdiet faucibus. | D47: =RANDBETWEEN(DATEVALUE("2020/01/01"),DATEVALUE("2025/01/01")) -> 43923 | E47: =INDEX(Reference!D:D,RANDBETWEEN(2,4)) -> Gama | F47: =INDEX(Reference!C:C,RANDBETWEEN(2,7))&"#"&RANDBETWEEN(10,300) -> GHJK#43 | G47: 常朵尾耳吉什象嗎園苦人十地到樹雞會西波？那它物夏兩來干做雪歡車直想功收言，合兄入抓想亮把止清牙多田抱飛背丟毛「得黃路交誰頭化半姐」帶早成綠斤片七。
A48: =INDEX(Reference!A:A,RANDBETWEEN(2,6)) -> F16 | B48: =INDEX(Reference!B:B,RANDBETWEEN(2,4))&"-"&ROW(A48) -> BBB-48 | C48: Duis aliquam libero imperdiet rutrum viverra. | D48: =RANDBETWEEN(DATEVALUE("2020/01/01"),DATEVALUE("2025/01/01")) -> 44389 | E48: =INDEX(Reference!D:D,RANDBETWEEN(2,4)) -> Suaya | F48: =INDEX(Reference!C:C,RANDBETWEEN(2,7))&"#"&RANDBETWEEN(10,300) -> GHJK#132 | G48: 澡間祖信，兔禾那吉奶，扒第九乾上坡；更婆汗合才哪從吃村丁浪叫打晚原，師西且美品亭澡彩白每讀前追弓以出？枝牙連荷和果你拍相回習這重汗意洋松、半過身封相。
A49: =INDEX(Reference!A:A,RANDBETWEEN(2,6)) -> F12 | B49: =INDEX(Reference!B:B,RANDBETWEEN(2,4))&"-"&ROW(A49) -> CCC-49 | C49: Vivamus nec odio fringilla, interdum tellus a, suscipit sapien. | D49: =RANDBETWEEN(DATEVALUE("2020/01/01"),DATEVALUE("2025/01/01")) -> 44902 | E49: =INDEX(Reference!D:D,RANDBETWEEN(2,4)) -> Gama | F49: =INDEX(Reference!C:C,RANDBETWEEN(2,7))&"#"&RANDBETWEEN(10,300) -> ZXCVB#237 | G49: 訴天念現良央朋進追。棵母比吃眼汁拉少師愛門頭急得昔把己連自肉？多即言干苦或一？多波北信過坡真請北路親火師紅，和包經止立牠立。
A50: =INDEX(Reference!A:A,RANDBETWEEN(2,6)) -> F15 | B50: =INDEX(Reference!B:B,RANDBETWEEN(2,4))&"-"&ROW(A50) -> CCC-50 | C50: Quisque et ligula et turpis iaculis tempor. | D50: =RANDBETWEEN(DATEVALUE("2020/01/01"),DATEVALUE("2025/01/01")) -> 44319 | E50: =INDEX(Reference!D:D,RANDBETWEEN(2,4)) -> Suaya | F50: =INDEX(Reference!C:C,RANDBETWEEN(2,7))&"#"&RANDBETWEEN(10,300) -> RTYU#63 | G50: 聽荷室錯家春昔巾借頁道亮出羊弓跟！親都苦午雲牠車果就貫汗甲。綠遠或。神丟樹雨八借支聲現五外多。完父怎坐經歌校更蝸成泉泉鳥住；秋完扒冰又。
A51: =INDEX(Reference!A:A,RANDBETWEEN(2,6)) -> F14 | B51: =INDEX(Reference!B:B,RANDBETWEEN(2,4))&"-"&ROW(A51) -> AAA-51 | C51: Mauris luctus sapien vel ante sollicitudin, sed facilisis turpis tincidunt. | D51: =RANDBETWEEN(DATEVALUE("2020/01/01"),DATEVALUE("2025/01/01")) -> 45101 | E51: =INDEX(Reference!D:D,RANDBETWEEN(2,4)) -> Suaya | F51: =INDEX(Reference!C:C,RANDBETWEEN(2,7))&"#"&RANDBETWEEN(10,300) -> GHJK#198 | G51: 掃具千收足很、說夕鴨澡玉課；根邊許目室道大十歌珠嗎黃幾得歌有即坐；課裝力自成抱支起沒室或法新意雨，說反話看夕，車條心位自斤經半從眼豆采車子種洋追幾雞常，免戊是羽足世您祖泉國像。
A52: =INDEX(Reference!A:A,RANDBETWEEN(2,6)) -> F12 | B52: =INDEX(Reference!B:B,RANDBETWEEN(2,4))&"-"&ROW(A52) -> CCC-52 | C52: Integer commodo lorem at orci maximus ullamcorper. | D52: =RANDBETWEEN(DATEVALUE("2020/01/01"),DATEVALUE("2025/01/01")) -> 45319 | E52: =INDEX(Reference!D:D,RANDBETWEEN(2,4)) -> Bala | F52: =INDEX(Reference!C:C,RANDBETWEEN(2,7))&"#"&RANDBETWEEN(10,300) -> ASDFG#248 | G52: 得西氣菜連流！草事蝶鼻弟您人從牙巾民。中常村羊發那造定、什流看貫怕氣松弓安很急牠禾蝴唱，吃巾百旦牛姐好七犬！親間內忍。
A53: =INDEX(Reference!A:A,RANDBETWEEN(2,6)) -> F16 | B53: =INDEX(Reference!B:B,RANDBETWEEN(2,4))&"-"&ROW(A53) -> AAA-53 | C53: Pellentesque vitae tortor malesuada, rhoncus ligula in, volutpat neque. | D53: =RANDBETWEEN(DATEVALUE("2020/01/01"),DATEVALUE("2025/01/01")) -> 45271 | E53: =INDEX(Reference!D:D,RANDBETWEEN(2,4)) -> Suaya | F53: =INDEX(Reference!C:C,RANDBETWEEN(2,7))&"#"&RANDBETWEEN(10,300) -> QWERT#267 | G53: 法亭已你坐黃杯半開學，游喜合服穿乍節象娘聲綠雲媽種寫幼合林語？經夏麻笑合東至幸唱棵幸飛青苗汗申哥旦入、師他拍更黑草，對苗幾！汁喜多！爬石間綠石校忍跑飽。
A54: =INDEX(Reference!A:A,RANDBETWEEN(2,6)) -> F18 | B54: =INDEX(Reference!B:B,RANDBETWEEN(2,4))&"-"&ROW(A54) -> CCC-54 | C54: Sed non nisl molestie, ultricies nisl eu, tincidunt nunc. | D54: =RANDBETWEEN(DATEVALUE("2020/01/01"),DATEVALUE("2025/01/01")) -> 44577 | E54: =INDEX(Reference!D:D,RANDBETWEEN(2,4)) -> Bala | F54: =INDEX(Reference!C:C,RANDBETWEEN(2,7))&"#"&RANDBETWEEN(10,300) -> ASDFG#168 | G54: 京重固老巴結女昌年斥有躲跑因鴨家朋；對尼工飽足呀反象未平成節二動春皮。太消寺送哪天，裏雞給貓訴禾向澡再停丁次戶收。多他蝸成早鼻的几正兩久荷頭「國科」子家的娘。瓜地就說食夏世乙。
A55: =INDEX(Reference!A:A,RANDBETWEEN(2,6)) -> F15 | B55: =INDEX(Reference!B:B,RANDBETWEEN(2,4))&"-"&ROW(A55) -> AAA-55 | C55: Etiam sit amet est ullamcorper, elementum metus sit amet, tincidunt lorem. | D55: =RANDBETWEEN(DATEVALUE("2020/01/01"),DATEVALUE("2025/01/01")) -> 44223 | E55: =INDEX(Reference!D:D,RANDBETWEEN(2,4)) -> Gama | F55: =INDEX(Reference!C:C,RANDBETWEEN(2,7))&"#"&RANDBETWEEN(10,300) -> RTYU#61 | G55: 爬斤手節皮瓜放「夏好果三象」各男。
A56: =INDEX(Reference!A:A,RANDBETWEEN(2,6)) -> F12 | B56: =INDEX(Reference!B:B,RANDBETWEEN(2,4))&"-"&ROW(A56) -> BBB-56 | C56: Nam in ante fermentum, condimentum augue sit amet, fringilla sapien. | D56: =RANDBETWEEN(DATEVALUE("2020/01/01"),DATEVALUE("2025/01/01")) -> 44288 | E56: =INDEX(Reference!D:D,RANDBETWEEN(2,4)) -> Bala | F56: =INDEX(Reference!C:C,RANDBETWEEN(2,7))&"#"&RANDBETWEEN(10,300) -> ZXCVB#86 | G56: 方一鳥見誰封羊的記嗎抱他父這
A57: =INDEX(Reference!A:A,RANDBETWEEN(2,6)) -> F18 | B57: =INDEX(Reference!B:B,RANDBETWEEN(2,4))&"-"&ROW(A57) -> CCC-57 | C57: Phasellus mollis erat non diam iaculis aliquam. | D57: =RANDBETWEEN(DATEVALUE("2020/01/01"),DATEVALUE("2025/01/01")) -> 44028 | E57: =INDEX(Reference!D:D,RANDBETWEEN(2,4)) -> Suaya | F57: =INDEX(Reference!C:C,RANDBETWEEN(2,7))&"#"&RANDBETWEEN(10,300) -> ASDFG#11 | G57: 別背遠昌了平且回意高，告每師玉朱樹食虎鼻根汁玩次元筆，給央一者皮到胡對對方立，加笑少天苦、山坡右買里媽知忍空弓羊讀蝸星主汁星只歡己，隻事寫飛反飛洋西三送生目未對；扒力聲登。
... A83: =INDEX(Reference!A:A,RANDBETWEEN(2,6)) -> F14 | B83: =INDEX(Reference!B:B,RANDBETWEEN(2,4))&"-"&ROW(A83) -> CCC-83 | C83: Nulla efficitur erat ultrices enim tristique, quis varius nunc iaculis. | D83: =RANDBETWEEN(DATEVALUE("2020/01/01"),DATEVALUE("2025/01/01")) -> 43912 | E83: =INDEX(Reference!D:D,RANDBETWEEN(2,4)) -> Gama | F83: =INDEX(Reference!C:C,RANDBETWEEN(2,7))&"#"&RANDBETWEEN(10,300) -> ZXCVB#98 | G83: 兔買記胡欠看入我免旁犬的下視怎昌幫生前；背行肖話羽邊布坡入。冬主常友吹校教汁斤嗎，雲看是，光夕干巾。
A84: =INDEX(Reference!A:A,RANDBETWEEN(2,6)) -> F12 | B84: =INDEX(Reference!B:B,RANDBETWEEN(2,4))&"-"&ROW(A84) -> AAA-84 | C84: Mauris accumsan quam quis leo tempus rutrum. | D84: =RANDBETWEEN(DATEVALUE("2020/01/01"),DATEVALUE("2025/01/01")) -> 44448 | E84: =INDEX(Reference!D:D,RANDBETWEEN(2,4)) -> Suaya | F84: =INDEX(Reference!C:C,RANDBETWEEN(2,7))&"#"&RANDBETWEEN(10,300) -> CVBN#97
A85: =INDEX(Reference!A:A,RANDBETWEEN(2,6)) -> F18 | B85: =INDEX(Reference!B:B,RANDBETWEEN(2,4))&"-"&ROW(A85) -> AAA-85 | C85: Fusce aliquet nulla ac neque sodales, sed tincidunt purus bibendum. | D85: =RANDBETWEEN(DATEVALUE("2020/01/01"),DATEVALUE("2025/01/01")) -> 44362 | E85: =INDEX(Reference!D:D,RANDBETWEEN(2,4)) -> Suaya | F85: =INDEX(Reference!C:C,RANDBETWEEN(2,7))&"#"&RANDBETWEEN(10,300) -> ASDFG#197 | G85: 抱歌已千禾竹昔文訴彩只。蝴冒六後牛午、林尤定支氣大幸月爸支不司氣成犬爪葉彩黃豆，尺看冰羊。着原主扒年已錯知步河飽快，細空話南支哪植二米，找冬友毛兌法
A86: =INDEX(Reference!A:A,RANDBETWEEN(2,6)) -> F12 | B86: =INDEX(Reference!B:B,RANDBETWEEN(2,4))&"-"&ROW(A86) -> CCC-86 | C86: Fusce molestie nibh quis imperdiet dapibus. | D86: =RANDBETWEEN(DATEVALUE("2020/01/01"),DATEVALUE("2025/01/01")) -> 43852 | E86: =INDEX(Reference!D:D,RANDBETWEEN(2,4)) -> Suaya | F86: =INDEX(Reference!C:C,RANDBETWEEN(2,7))&"#"&RANDBETWEEN(10,300) -> CVBN#282 | G86: 念還綠師爬亮放圓大牛占十花寸
A87: =INDEX(Reference!A:A,RANDBETWEEN(2,6)) -> F18 | B87: =INDEX(Reference!B:B,RANDBETWEEN(2,4))&"-"&ROW(A87) -> CCC-87 | C87: Donec suscipit est maximus volutpat bibendum. | D87: =RANDBETWEEN(DATEVALUE("2020/01/01"),DATEVALUE("2025/01/01")) -> 44068 | E87: =INDEX(Reference!D:D,RANDBETWEEN(2,4)) -> Suaya | F87: =INDEX(Reference!C:C,RANDBETWEEN(2,7))&"#"&RANDBETWEEN(10,300) -> QWERT#254 | G87: 未雞行方抓生土卜友想而動常耍事十姊欠，孝王蛋住巾，夏至哪羊京圓燈：呢加力京乙明怎父耍意間都校怕，幼白幫几。寺幼父。良植由天刃抱勿急時。
A88: =INDEX(Reference!A:A,RANDBETWEEN(2,6)) -> F12 | B88: =INDEX(Reference!B:B,RANDBETWEEN(2,4))&"-"&ROW(A88) -> CCC-88 | C88: Mauris eget lorem non enim bibendum condimentum eget sit amet libero. | D88: =RANDBETWEEN(DATEVALUE("2020/01/01"),DATEVALUE("2025/01/01")) -> 45380 | E88: =INDEX(Reference!D:D,RANDBETWEEN(2,4)) -> Gama | F88: =INDEX(Reference!C:C,RANDBETWEEN(2,7))&"#"&RANDBETWEEN(10,300) -> ASDFG#276 | G88: 媽英念耍父蝶目，友喜扒園汁別親珠耳米合眼布起重胡想已午，晚房晚前菜字同紅六？節小金乙吉車定村哪福錯坡幸具會音斥服流，耳十斤請重旁兔都根點北共扒各爪男犬用香候。
A89: =INDEX(Reference!A:A,RANDBETWEEN(2,6)) -> F18 | B89: =INDEX(Reference!B:B,RANDBETWEEN(2,4))&"-"&ROW(A89) -> CCC-89 | C89: Aenean at nunc hendrerit, imperdiet mauris nec, vehicula nunc. | D89: =RANDBETWEEN(DATEVALUE("2020/01/01"),DATEVALUE("2025/01/01")) -> 44024 | E89: =INDEX(Reference!D:D,RANDBETWEEN(2,4)) -> Suaya | F89: =INDEX(Reference!C:C,RANDBETWEEN(2,7))&"#"&RANDBETWEEN(10,300) -> QWERT#184 | G89: 毛戶眼面弓好白哭、親首昌許好意住尾，良能追錯夏冒牛，尼珠國問方一固放裝問山面教首定和頁跟；動個示故都同向「好魚小細火童」童衣貫兩過以家日，開做穿。四步目馬公世怪蝴我叫童語相。
A90: =INDEX(Reference!A:A,RANDBETWEEN(2,6)) -> F12 | B90: =INDEX(Reference!B:B,RANDBETWEEN(2,4))&"-"&ROW(A90) -> CCC-90 | C90: Proin efficitur leo non nibh efficitur placerat. | D90: =RANDBETWEEN(DATEVALUE("2020/01/01"),DATEVALUE("2025/01/01")) -> 44075 | E90: =INDEX(Reference!D:D,RANDBETWEEN(2,4)) -> Suaya | F90: =INDEX(Reference!C:C,RANDBETWEEN(2,7))&"#"&RANDBETWEEN(10,300) -> ASDFG#45 | G90: 哭生鴨吧固裝給故着幼胡幸足玉原有唱原的服？干吉十何幼經太很菜荷荷寺雄肉員前急，候千海原亭歌念校會占去直麻。
A91: =INDEX(Reference!A:A,RANDBETWEEN(2,6)) -> F14 | B91: =INDEX(Reference!B:B,RANDBETWEEN(2,4))&"-"&ROW(A91) -> AAA-91 | C91: Donec fermentum nunc quis felis maximus, vel mattis velit ullamcorper. | D91: =RANDBETWEEN(DATEVALUE("2020/01/01"),DATEVALUE("2025/01/01")) -> 45295 | E91: =INDEX(Reference!D:D,RANDBETWEEN(2,4)) -> Gama | F91: =INDEX(Reference!C:C,RANDBETWEEN(2,7))&"#"&RANDBETWEEN(10,300) -> QWERT#249
A92: =INDEX(Reference!A:A,RANDBETWEEN(2,6)) -> F18 | B92: =INDEX(Reference!B:B,RANDBETWEEN(2,4))&"-"&ROW(A92) -> AAA-92 | C92: Etiam tempor lectus cursus elementum cursus. | D92: =RANDBETWEEN(DATEVALUE("2020/01/01"),DATEVALUE("2025/01/01")) -> 44520 | E92: =INDEX(Reference!D:D,RANDBETWEEN(2,4)) -> Gama | F92: =INDEX(Reference!C:C,RANDBETWEEN(2,7))&"#"&RANDBETWEEN(10,300) -> ZXCVB#44 | G92: 平這欠書借很刀三吃河？斥汁夏來加有掃果鼻院即看姐錯二種看朋課，綠鴨欠訴、鴨品服刃和光室八問棵寺科再左枝放，兆西的。是愛說停頭他蝶很弓重枝民實麻神美波年實，它丁唱身音哭親大。
A93: =INDEX(Reference!A:A,RANDBETWEEN(2,6)) -> F16 | B93: =INDEX(Reference!B:B,RANDBETWEEN(2,4))&"-"&ROW(A93) -> BBB-93 | C93: Cras pellentesque nulla sed suscipit tristique. | D93: =RANDBETWEEN(DATEVALUE("2020/01/01"),DATEVALUE("2025/01/01")) -> 45451 | E93: =INDEX(Reference!D:D,RANDBETWEEN(2,4)) -> Bala | F93: =INDEX(Reference!C:C,RANDBETWEEN(2,7))&"#"&RANDBETWEEN(10,300) -> ZXCVB#244 | G93: 年南共送共登位笑經門貝麻秋人背穴辛爪香出，怕麼給到經工。旁請品士尤丁山毛訴犬田員母肉「山」助回寸買流美奶她！雞背歡九枝消光苦五愛左民，六元即品荷入起五對種交泉彩燈丟貫己新巴。
A94: =INDEX(Reference!A:A,RANDBETWEEN(2,6)) -> F16 | B94: =INDEX(Reference!B:B,RANDBETWEEN(2,4))&"-"&ROW(A94) -> AAA-94 | C94: Sed elementum erat quis diam fermentum vehicula. | D94: =RANDBETWEEN(DATEVALUE("2020/01/01"),DATEVALUE("2025/01/01")) -> 45470 | E94: =INDEX(Reference!D:D,RANDBETWEEN(2,4)) -> Gama | F94: =INDEX(Reference!C:C,RANDBETWEEN(2,7))&"#"&RANDBETWEEN(10,300) -> CVBN#238 | G94: 又半主嗎朵一今追詞娘下來，士春植裝草乙方你哪犬蝸乾能衣風丁胡汗；姊斤魚沒，王化帶條帽只告鴨裏背圓足乙坡可化住掃。衣世九開牛書首做頭園外五，交旦助親害麼話八春且黑河。豆蛋昌今朵西口。問木往位天從。
A95: =INDEX(Reference!A:A,RANDBETWEEN(2,6)) -> F18 | B95: =INDEX(Reference!B:B,RANDBETWEEN(2,4))&"-"&ROW(A95) -> CCC-95 | C95: Duis posuere justo viverra arcu mollis ultrices. | D95: =RANDBETWEEN(DATEVALUE("2020/01/01"),DATEVALUE("2025/01/01")) -> 44039 | E95: =INDEX(Reference!D:D,RANDBETWEEN(2,4)) -> Suaya | F95: =INDEX(Reference!C:C,RANDBETWEEN(2,7))&"#"&RANDBETWEEN(10,300) -> QWERT#294 | G95: 說荷讀穿掃時冰開香害住兌起候；未害貓文中生星豆拉拍、麼南喜新息立的飛士，辛它斗尤字者空條聲了鳥請即幸，愛司占休鴨歌欠新面空親什紅男去，申香生拍打放要弟幸。
...

Sheet Reference
A1: Fab | B1: Issue Key | C1: Tool ID | D1: Creater
A2: F12 | B2: AAA | C2: QWERT | D2: Bala
A3: F14 | B3: BBB | C3: ASDFG | D3: Gama
A4: F15 | B4: CCC | C4: ZXCVB | D4: Suaya
A5: F16 | C5: RTYU
A6: F18 | C6: GHJK
C7: CVBN
